Workbook

Sheet matlab
A1: 1998 | B1: ='raw data'!J8 -> 3.1840035 | C1: ='raw data'!K8 -> 1.0018466 | D1: ='raw data'!L8 -> 4.7401985 | E1: ='raw data'!M8 -> 0.80332669 | F1: 90.97
A2: =+A1+0.25 -> 1998.25 | B2: ='raw data'!J9 -> 2.4394774 | C2: ='raw data'!K9 -> 0.78940199 | D2: ='raw data'!L9 -> 4.7351996 | E2: ='raw data'!M9 -> 1.6821301 | F2: 91.98
A3: =+A2+0.25 -> 1998.5 | B3: ='raw data'!J10 -> 2.6024719 | C3: ='raw data'!K10 -> 0.90759659 | D3: ='raw data'!L10 -> 4.7169763 | E3: ='raw data'!M10 -> -0.67395977 | F3: 91.39
A4: =+A3+0.25 -> 1998.75 | B4: ='raw data'!J11 -> 3.4107569 | C4: ='raw data'!K11 -> 0.72550675 | D4: ='raw data'!L11 -> 4.7072674 | E4: ='raw data'!M11 -> -3.2902818 | F4: 91.27
A5: =+A4+0.25 -> 1999 | B5: ='raw data'!J12 -> 1.7482146 | C5: ='raw data'!K12 -> 0.70326443 | D5: ='raw data'!L12 -> 4.7039828 | E5: ='raw data'!M12 -> 0.019192532 | F5: 90.55
A6: =+A5+0.25 -> 1999.25 | B6: ='raw data'!J13 -> 2.3465785 | C6: ='raw data'!K13 -> 0.73701936 | D6: ='raw data'!L13 -> 4.7157311 | E6: ='raw data'!M13 -> 0.272465 | F6: 90.14
A7: =+A6+0.25 -> 1999.5 | B7: ='raw data'!J14 -> 1.5977218 | C7: ='raw data'!K14 -> 0.58838267 | D7: ='raw data'!L14 -> 4.6633153 | E7: ='raw data'!M14 -> 2.0875808 | F7: 90.54
A8: =+A7+0.25 -> 1999.75 | B8: ='raw data'!J15 -> 1.6372148 | C8: ='raw data'!K15 -> 0.57254864 | D8: ='raw data'!L15 -> 4.6190543 | E8: ='raw data'!M15 -> 2.5999692 | F8: 90.85
A9: =+A8+0.25 -> 2000 | B9: ='raw data'!J16 -> 1.4623907 | C9: ='raw data'!K16 -> 0.72679191 | D9: ='raw data'!L16 -> 4.6847753 | E9: ='raw data'!M16 -> 0.94034525 | F9: 91.11
A10: =+A9+0.25 -> 2000.25 | B10: ='raw data'!J17 -> 1.8338143 | C10: ='raw data'!K17 -> 0.80863116 | D10: ='raw data'!L17 -> 4.6992387 | E10: ='raw data'!M17 -> 0.2214489 | F10: 90.58
A11: =+A10+0.25 -> 2000.5 | B11: ='raw data'!J18 -> 1.0105445 | C11: ='raw data'!K18 -> 0.92588271 | D11: ='raw data'!L18 -> 4.6468906 | E11: ='raw data'!M18 -> 1.5439196 | F11: 90.81
A12: =+A11+0.25 -> 2000.75 | B12: ='raw data'!J19 -> 2.0563538 | C12: ='raw data'!K19 -> 0.81138769 | D12: ='raw data'!L19 -> 4.6406377 | E12: ='raw data'!M19 -> 1.1667927 | F12: 90.53
A13: =+A12+0.25 -> 2001 | B13: ='raw data'!J20 -> 0.839311 | C13: ='raw data'!K20 -> 0.57664149 | D13: ='raw data'!L20 -> 4.6377171 | E13: ='raw data'!M20 -> 0.69431064 | F13: 90.42
... A98: =+A97+0.25 -> 2022.25 | B98: ='raw data'!J105 -> 2.0917801 | C98: ='raw data'!K105 -> 0.26808668 | D98: ='raw data'!L105 -> 4.4471672 | E98: ='raw data'!M105 -> -0.0070227442 | F98: 104.71

Sheet raw data
B1: gross domestic product | C1: real exchange rate | D1: 3-month tbill rate | E1: consumer price inflation | F1: cpi inflation | G1: 3-month tbill rate | H1: gdp price deflator | I1: def inflation | J1: domestic interest rate | K1: foreign interest rate | L1: log reer | M1: gdp growth | N1: TOT index | O1: tot index brecha | P1: tot growth
A2: short | B2: gdp | C2: reer | D2: tbillch | E2: cpi | F2: cpiinf | G2: tbillus | H2: def | I2: definf | J2: rd | K2: re | L2: lnreer | M2: rgdpg | N2: tot
A3: country | B3: chile | C3: chile | D3: chile | E3: chile | F3: chile | G3: usa | H3: usa | I3: usa | J3: chile | K3: chile | L3: chile | M3: chile | N3: chile
A4: units | B4: mmm clp | C4: index | D4: % per anm. | E4: index | F4: % per qtr. | G4: % per anm. | H4: index | I4: % per qtr. | J4: % per qtr. | K4: % per qtr. | L4: log of index | M4: % per qtr. | N4: index
A5: source | B5: bcch | C5: ifs-imf | D5: bcch | E5: ifs-imf | F5: own | G5: fred | H5: ifs-imf | I5: own | J5: own | K5: own | L5: own | M5: own | N5: imf
A6: type | B6: real | C6: real | D6: nominal | E6: nominal | F6: nominal | G6: nominal | H6: nominal | I6: nominal | J6: real | K6: real | L6: real | M6: real | N6: nominal
A7: sa | B7: yes | C7: no | D7: no | E7: no | F7: no | G7: no | H7: yes | I7: yes | J7: no | K7: no | L7: no | M7: yes | N7: no
A8: 1998 | B8: 22825.629 | C8: 114.45692 | D8: 17.253333 | E8: 67.583917 | G8: 5.0533333 | H8: 77.875625 | J8: =100 * ((1 + D8 * 0.01) ^ 0.25 / (1 + F9 * 0.01) - 1) -> 3.1840035 | K8: =100 * ((1 + G8 * 0.01) ^ 0.25 / (1 + I9 * 0.01) - 1) -> 1.0018466 | L8: =LN(C8) -> 4.7401985 | M8: 0.80332669 | N8: 90.97 | O8: 0.2478395 | P8: -0.2989841
A9: =+A8+0.25 -> 1998.25 | B9: 23212.833 | C9: 113.88618 | D9: 15.11 | E9: 68.159725 | F9: =100*(LN(E9)-LN(E8)) -> 0.84837978 | G9: 4.9766667 | H9: 78.059524 | I9: =100*(LN(H9)-LN(H8)) -> 0.23586567 | J9: =100 * ((1 + D9 * 0.01) ^ 0.25 / (1 + F10 * 0.01) - 1) -> 2.4394774 | K9: =100 * ((1 + G9 * 0.01) ^ 0.25 / (1 + I10 * 0.01) - 1) -> 0.78940199 | L9: =LN(C9) -> 4.7351996 | M9: =100 * (LN(B9) - LN(B8)) -> 1.6821301 | N9: 91.98 | O9: 1.450593 | P9: 1.013535
A10: =+A9+0.25 -> 1998.5 | B10: 23056.914 | C10: 111.8296 | D10: 17.565 | E10: 68.923208 | F10: =100*(LN(E10)-LN(E9)) -> 1.1139111 | G10: 4.8233333 | H10: 78.394971 | I10: =100*(LN(H10)-LN(H9)) -> 0.4288122 | J10: =100 * ((1 + D10 * 0.01) ^ 0.25 / (1 + F11 * 0.01) - 1) -> 2.6024719 | K10: =100 * ((1 + G10 * 0.01) ^ 0.25 / (1 + I11 * 0.01) - 1) -> 0.90759659 | L10: =LN(C10) -> 4.7169763 | M10: =100 * (LN(B10) - LN(B9)) -> -0.67395977 | N10: 91.39 | O10: 0.8845921 | P10: -0.5905304
A11: =+A10+0.25 -> 1998.75 | B11: 22310.621 | C11: 110.74911 | D11: 15.72 | E11: 69.955962 | F11: =100*(LN(E11)-LN(E10)) -> 1.4872976 | G11: 4.2533333 | H11: 78.610484 | I11: =100*(LN(H11)-LN(H10)) -> 0.27452864 | J11: =100 * ((1 + D11 * 0.01) ^ 0.25 / (1 + F12 * 0.01) - 1) -> 3.4107569 | K11: =100 * ((1 + G11 * 0.01) ^ 0.25 / (1 + I12 * 0.01) - 1) -> 0.72550675 | L11: =LN(C11) -> 4.7072674 | M11: =100 * (LN(B11) - LN(B10)) -> -3.2902818 | N11: 91.27 | O11: 0.8341244 | P11: -0.1219101
A12: =+A11+0.25 -> 1999 | B12: 22314.904 | C12: 110.38595 | D12: 11.293333 | E12: 70.163788 | F12: =100*(LN(E12)-LN(E11)) -> 0.29664116 | G12: 4.4066667 | H12: 78.861621 | I12: =100*(LN(H12)-LN(H11)) -> 0.31896121 | J12: =100 * ((1 + D12 * 0.01) ^ 0.25 / (1 + F13 * 0.01) - 1) -> 1.7482146 | K12: =100 * ((1 + G12 * 0.01) ^ 0.25 / (1 + I13 * 0.01) - 1) -> 0.70326443 | L12: =LN(C12) -> 4.7039828 | M12: =100 * (LN(B12) - LN(B11)) -> 0.019192532 | N12: 90.55 | O12: 0.1157518 | P12: -0.7233276
A13: =+A12+0.25 -> 1999.25 | B13: 22375.787 | C13: 111.69044 | D13: 11.526667 | E13: 70.830914 | F13: =100*(LN(E13)-LN(E12)) -> 0.94631971 | G13: 4.4533333 | H13: 79.160277 | I13: =100*(LN(H13)-LN(H12)) -> 0.37799315 | J13: =100 * ((1 + D13 * 0.01) ^ 0.25 / (1 + F14 * 0.01) - 1) -> 2.3465785 | K13: =100 * ((1 + G13 * 0.01) ^ 0.25 / (1 + I14 * 0.01) - 1) -> 0.73701936 | L13: =LN(C13) -> 4.7157311 | M13: =100 * (LN(B13) - LN(B12)) -> 0.272465 | N13: 90.14 | O13: -0.2585973 | P13: -0.4068909
A14: =+A13+0.25 -> 1999.5 | B14: 22847.809 | C14: 105.98688 | D14: 9.8666667 | E14: 71.120993 | F14: =100*(LN(E14)-LN(E13)) -> 0.40870174 | G14: 4.65 | H14: 79.442247 | I14: =100*(LN(H14)-LN(H13)) -> 0.35556938 | J14: =100 * ((1 + D14 * 0.01) ^ 0.25 / (1 + F15 * 0.01) - 1) -> 1.5977218 | K14: =100 * ((1 + G14 * 0.01) ^ 0.25 / (1 + I15 * 0.01) - 1) -> 0.58838267 | L14: =LN(C14) -> 4.6633153 | M14: =100 * (LN(B14) - LN(B13)) -> 2.0875808 | N14: 90.54 | O14: 0.2474767 | P14: 0.3952255
A15: =+A14+0.25 -> 1999.75 | B15: 23449.635 | C15: 101.39809 | D15: 11.133333 | E15: 71.670948 | F15: =100*(LN(E15)-LN(E14)) -> 0.77029216 | G15: 5.0433333 | H15: 79.881291 | I15: =100*(LN(H15)-LN(H14)) -> 0.55113632 | J15: =100 * ((1 + D15 * 0.01) ^ 0.25 / (1 + F16 * 0.01) - 1) -> 1.6372148 | K15: =100 * ((1 + G15 * 0.01) ^ 0.25 / (1 + I16 * 0.01) - 1) -> 0.57254864 | L15: =LN(C15) -> 4.6190543 | M15: =100 * (LN(B15) - LN(B14)) -> 2.5999692 | N15: 90.85 | O15: 0.6545576 | P15: 0.3136673
A16: =+A15+0.25 -> 2000 | B16: 23671.183 | C16: 108.28593 | D16: 11.883333 | E16: 72.405896 | F16: =100*(LN(E16)-LN(E15)) -> 1.0202246 | G16: 5.52 | H16: 80.411321 | I16: =100*(LN(H16)-LN(H15)) -> 0.66133083 | J16: =100 * ((1 + D16 * 0.01) ^ 0.25 / (1 + F17 * 0.01) - 1) -> 1.4623907 | K16: =100 * ((1 + G16 * 0.01) ^ 0.25 / (1 + I17 * 0.01) - 1) -> 0.72679191 | L16: =LN(C16) -> 4.6847753 | M16: =100 * (LN(B16) - LN(B15)) -> 0.94034525 | N16: 91.11 | O16: 0.9924708 | P16: 0.2612915
A17: =+A16+0.25 -> 2000.25 | B17: 23723.66 | C17: 109.8635 | D17: 10.716667 | E17: 73.40071 | F17: =100*(LN(E17)-LN(E16)) -> 1.3645876 | G17: 5.7133333 | H17: 80.912241 | I17: =100*(LN(H17)-LN(H16)) -> 0.6210149 | J17: =100 * ((1 + D17 * 0.01) ^ 0.25 / (1 + F18 * 0.01) - 1) -> 1.8338143 | K17: =100 * ((1 + G17 * 0.01) ^ 0.25 / (1 + I18 * 0.01) - 1) -> 0.80863116 | L17: =LN(C17) -> 4.6992387 | M17: =100 * (LN(B17) - LN(B16)) -> 0.2214489 | N17: 90.58 | O17: 0.4327561 | P17: -0.5356522
A18: =+A17+0.25 -> 2000.5 | B18: 24092.777 | C18: 104.2603 | D18: 9.8633333 | E18: 73.938908 | F18: =100*(LN(E18)-LN(E17)) -> 0.73055793 | G18: 6.0166667 | H18: 81.387249 | I18: =100*(LN(H18)-LN(H17)) -> 0.5853483 | J18: =100 * ((1 + D18 * 0.01) ^ 0.25 / (1 + F19 * 0.01) - 1) -> 1.0105445 | K18: =100 * ((1 + G18 * 0.01) ^ 0.25 / (1 + I19 * 0.01) - 1) -> 0.92588271 | L18: =LN(C18) -> 4.6468906 | M18: =100 * (LN(B18) - LN(B17)) -> 1.5439196 | N18: 90.81 | O18: 0.7115694 | P18: 0.2364197
A19: =+A18+0.25 -> 2000.75 | B19: 24375.536 | C19: 103.6104 | D19: 10.566667 | E19: 74.947826 | F19: =100*(LN(E19)-LN(E18)) -> 1.355304 | G19: 6.0166667 | H19: 81.828326 | I19: =100*(LN(H19)-LN(H18)) -> 0.5404859 | J19: =100 * ((1 + D19 * 0.01) ^ 0.25 / (1 + F20 * 0.01) - 1) -> 2.0563538 | K19: =100 * ((1 + G19 * 0.01) ^ 0.25 / (1 + I20 * 0.01) - 1) -> 0.81138769 | L19: =LN(C19) -> 4.6406377 | M19: =100 * (LN(B19) - LN(B18)) -> 1.1667927 | N19: 90.53 | O19: 0.3888272 | P19: -0.2871246
A20: =+A19+0.25 -> 2001 | B20: 24545.367 | C20: 103.30823 | D20: 7.5 | E20: 75.306068 | F20: =100*(LN(E20)-LN(E19)) -> 0.47684876 | G20: 4.8166667 | H20: 82.365792 | I20: =100*(LN(H20)-LN(H19)) -> 0.65467325 | J20: =100 * ((1 + D20 * 0.01) ^ 0.25 / (1 + F21 * 0.01) - 1) -> 0.839311 | K20: =100 * ((1 + G20 * 0.01) ^ 0.25 / (1 + I21 * 0.01) - 1) -> 0.57664149 | L20: =LN(C20) -> 4.6377171 | M20: =100 * (LN(B20) - LN(B19)) -> 0.69431064 | N20: 90.42 | O20: 0.2420128 | P20: -0.1060715
... A66: =+A65+0.25 -> 2012.5 | B66: 41450.26 | C66: 104.3356 | D66: 4.96 | E66: 106.39002 | F66: =100*(LN(E66)-LN(E65)) -> 0.20229818 | G66: 0.10333333 | H66: 104.2302 | I66: =100*(LN(H66)-LN(H65)) -> 0.51645794 | J66: =100 * ((1 + D66 * 0.01) ^ 0.25 / (1 + F67 * 0.01) - 1) -> 0.3812179 | K66: =100 * ((1 + G66 * 0.01) ^ 0.25 / (1 + I67 * 0.01) - 1) -> -0.47802369 | L66: =LN(C66) -> 4.6476126 | M66: =100 * (LN(B66) - LN(B65)) -> 0.77413031 | N66: 100.02 | O66: -0.8571762 | P66: -0.9959412
A67: =+A66+0.25 -> 2012.75 | B67: 41696.323 | C67: 104.34367 | D67: =(D66+D68)/2 -> 5.02 | E67: 107.28015 | F67: =100*(LN(E67)-LN(E66)) -> 0.83318721 | G67: 0.086666667 | H67: 104.75923 | I67: =100*(LN(H67)-LN(H66)) -> 0.50626709 | J67: =100 * ((1 + D67 * 0.01) ^ 0.25 / (1 + F68 * 0.01) - 1) -> 1.0176672 | K67: =100 * ((1 + G67 * 0.01) ^ 0.25 / (1 + I68 * 0.01) - 1) -> -0.37555254 | L67: =LN(C67) -> 4.64769 | M67: =100 * (LN(B67) - LN(B66)) -> 0.59188126 | N67: 100.83 | O67: 0.0362655 | P67: 0.813652
A68: =+A67+0.25 -> 2013 | B68: 42064.412 | C68: 105.06172 | D68: 5.08 | E68: 107.50806 | F68: =100*(LN(E68)-LN(E67)) -> 0.21221654 | G68: 0.086666667 | H68: 105.17774 | I68: =100*(LN(H68)-LN(H67)) -> 0.39870954 | J68: =100 * ((1 + D68 * 0.01) ^ 0.25 / (1 + F69 * 0.01) - 1) -> 1.2303044 | K68: =100 * ((1 + G68 * 0.01) ^ 0.25 / (1 + I69 * 0.01) - 1) -> -0.26137957 | L68: =LN(C68) -> 4.654548 | M68: =100 * (LN(B68) - LN(B67)) -> 0.8789099 | N68: 101.56 | O68: 0.8493915 | P68: 0.7292328
A69: =+A68+0.25 -> 2013.25 | B69: 42395.386 | C69: 102.94072 | D69: 4.9733333 | E69: 107.52526 | F69: =100*(LN(E69)-LN(E68)) -> 0.01599808 | G69: 0.05 | H69: 105.47664 | I69: =100*(LN(H69)-LN(H68)) -> 0.28378094 | J69: =100 * ((1 + D69 * 0.01) ^ 0.25 / (1 + F70 * 0.01) - 1) -> 0.1962405 | K69: =100 * ((1 + G69 * 0.01) ^ 0.25 / (1 + I70 * 0.01) - 1) -> -0.45547105 | L69: =LN(C69) -> 4.6341533 | M69: =100 * (LN(B69) - LN(B68)) -> 0.7837484 | N69: 100.17 | O69: -0.4408868 | P69: -1.38739
A70: =+A69+0.25 -> 2013.5 | B70: 42630.216 | C70: 99.786804 | D70: 4.815 | E70: 108.6304 | F70: =100*(LN(E70)-LN(E69)) -> 1.0225485 | G70: 0.033333333 | H70: 105.97367 | I70: =100*(LN(H70)-LN(H69)) -> 0.47010992 | J70: =100 * ((1 + D70 * 0.01) ^ 0.25 / (1 + F71 * 0.01) - 1) -> 0.15315988 | K70: =100 * ((1 + G70 * 0.01) ^ 0.25 / (1 + I71 * 0.01) - 1) -> -0.58401146 | L70: =LN(C70) -> 4.603036 | M70: =100 * (LN(B70) - LN(B69)) -> 0.5523751 | N70: 99.15 | O70: -1.378525 | P70: -1.025841
A71: =+A70+0.25 -> 2013.75 | B71: 42811.096 | C71: 97.661104 | D71: =(D70+D72)/2 -> 4.5208333 | E71: 109.75274 | F71: =100*(LN(E71)-LN(E70)) -> 1.0278716 | G71: 0.063333333 | H71: 106.60697 | I71: =100*(LN(H71)-LN(H70)) -> 0.59582343 | J71: =100 * ((1 + D71 * 0.01) ^ 0.25 / (1 + F72 * 0.01) - 1) -> -0.18617667 | K71: =100 * ((1 + G71 * 0.01) ^ 0.25 / (1 + I72 * 0.01) - 1) -> -0.39839425 | L71: =LN(C71) -> 4.5815034 | M71: =100 * (LN(B71) - LN(B70)) -> 0.42340309 | N71: 99.89 | O71: -0.5635812 | P71: 0.7443466
A72: =+A71+0.25 -> 2014 | B72: 42979.119 | C72: 93.05437 | D72: 4.2266667 | E72: 111.18899 | F72: =100*(LN(E72)-LN(E71)) -> 1.3001351 | G72: 0.046666667 | H72: 107.05125 | I72: =100*(LN(H72)-LN(H71)) -> 0.41588067 | J72: =100 * ((1 + D72 * 0.01) ^ 0.25 / (1 + F73 * 0.01) - 1) -> -0.53208681 | K72: =100 * ((1 + G72 * 0.01) ^ 0.25 / (1 + I73 * 0.01) - 1) -> -0.54955037 | L72: =LN(C72) -> 4.5331839 | M72: =100 * (LN(B72) - LN(B71)) -> 0.39170699 | N72: 100.59 | O72: 0.1945494 | P72: 0.696846
A73: =+A72+0.25 -> 2014.25 | B73: 43254.31 | C73: 92.54111 | D73: 3.835 | E73: 112.96065 | F73: =100*(LN(E73)-LN(E72)) -> 1.5808179 | G73: 0.033333333 | H73: 107.65706 | I73: =100*(LN(H73)-LN(H72)) -> 0.56431619 | J73: =100 * ((1 + D73 * 0.01) ^ 0.25 / (1 + F74 * 0.01) - 1) -> 0.069137582 | K73: =100 * ((1 + G73 * 0.01) ^ 0.25 / (1 + I74 * 0.01) - 1) -> -0.42524068 | L73: =LN(C73) -> 4.527653 | M73: =100 * (LN(B73) - LN(B72)) -> 0.63824981 | N73: 99.05 | O73: -1.283644 | P73: -1.535049
A74: =+A73+0.25 -> 2014.5 | B74: 43051.705 | C74: 90.414149 | D74: 3.77 | E74: 113.95399 | F74: =100*(LN(E74)-LN(E73)) -> 0.87551963 | G74: 0.026666667 | H74: 108.12685 | I74: =100*(LN(H74)-LN(H73)) -> 0.43542458 | J74: =100 * ((1 + D74 * 0.01) ^ 0.25 / (1 + F75 * 0.01) - 1) -> -0.63669523 | K74: =100 * ((1 + G74 * 0.01) ^ 0.25 / (1 + I75 * 0.01) - 1) -> -0.1592715 | L74: =LN(C74) -> 4.5044008 | M74: =100 * (LN(B74) - LN(B73)) -> -0.46950554 | N74: 99.77 | O74: -0.5347537 | P74: 0.7151031
A75: =+A74+0.25 -> 2014.75 | B75: 43552.762 | C75: 91.501733 | D75: =(D74+D76)/2 -> 3.1216667 | E75: 115.76435 | F75: =100*(LN(E75)-LN(E74)) -> 1.5761918 | G75: 0.023333333 | H75: 108.30671 | I75: =100*(LN(H75)-LN(H74)) -> 0.16620221 | J75: =100 * ((1 + D75 * 0.01) ^ 0.25 / (1 + F76 * 0.01) - 1) -> 0.52158015 | K75: =100 * ((1 + G75 * 0.01) ^ 0.25 / (1 + I76 * 0.01) - 1) -> 0.041353487 | L75: =LN(C75) -> 4.5163579 | M75: =100 * (LN(B75) - LN(B74)) -> 1.157129 | N75: 99.57 | O75: -0.7096291 | P75: -0.1951294
A76: =+A75+0.25 -> 2015 | B76: 43890.52 | C76: 91.882941 | D76: 2.4733333 | E76: 116.05246 | F76: =100*(LN(E76)-LN(E75)) -> 0.24856716 | G76: 0.026666667 | H76: 108.26826 | I76: =100*(LN(H76)-LN(H75)) -> -0.035505981 | J76: =100 * ((1 + D76 * 0.01) ^ 0.25 / (1 + F77 * 0.01) - 1) -> -0.77112508 | K76: =100 * ((1 + G76 * 0.01) ^ 0.25 / (1 + I77 * 0.01) - 1) -> -0.53062197 | L76: =LN(C76) -> 4.5205154 | M76: =100 * (LN(B76) - LN(B75)) -> 0.77252143 | N76: 100.58 | O76: 0.2973521 | P76: 1.00779
A77: =+A76+0.25 -> 2015.25 | B77: 44234.002 | C77: 94.249303 | D77: 2.94 | E77: 117.68222 | F77: =100*(LN(E77)-LN(E76)) -> 1.3945585 | G77: 0.02 | H77: 108.85466 | I77: =100*(LN(H77)-LN(H76)) -> 0.54015415 | J77: =100 * ((1 + D77 * 0.01) ^ 0.25 / (1 + F78 * 0.01) - 1) -> -0.68191133 | K77: =100 * ((1 + G77 * 0.01) ^ 0.25 / (1 + I78 * 0.01) - 1) -> -0.29183571 | L77: =LN(C77) -> 4.5459434 | M77: =100 * (LN(B77) - LN(B76)) -> 0.77954234 | N77: 100.05 | O77: -0.2476146 | P77: -0.5300751
A78: =+A77+0.25 -> 2015.5 | B78: 44038.916 | C78: 89.223914 | D78: =+D77*(0.666666666666667) + D80*(0.333333333333333) -> 3.1511111 | E78: 119.36358 | F78: =100*(LN(E78)-LN(E77)) -> 1.4186179 | G78: 0.04 | H78: 109.17921 | I78: =100*(LN(H78)-LN(H77)) -> 0.29770414 | J78: =100 * ((1 + D78 * 0.01) ^ 0.25 / (1 + F79 * 0.01) - 1) -> -0.1734295 | K78: =100 * ((1 + G78 * 0.01) ^ 0.25 / (1 + I79 * 0.01) - 1) -> 0.019011733 | L78: =LN(C78) -> 4.4911491 | M78: =100 * (LN(B78) - LN(B77)) -> -0.44200674 | N78: 98.9 | O78: -1.433806 | P78: -1.154373
A79: =+A78+0.25 -> 2015.75 | B79: 44380.079 | C79: 88.645501 | D79: =+D77*(1/3) + D80*(2/3) -> 3.3622222 | E79: 120.50742 | F79: =100*(LN(E79)-LN(E78)) -> 0.9537199 | G79: 0.12333333 | H79: 109.16937 | I79: =100*(LN(H79)-LN(H78)) -> -0.0090115194 | J79: =100 * ((1 + D79 * 0.01) ^ 0.25 / (1 + F80 * 0.01) - 1) -> 0.051325846 | K79: =100 * ((1 + G79 * 0.01) ^ 0.25 / (1 + I80 * 0.01) - 1) -> 0.11110328 | L79: =LN(C79) -> 4.4846453 | M79: =100 * (LN(B79) - LN(B78)) -> 0.77169935 | N79: 99.3 | O79: -1.082361 | P79: 0.4080276
A80: =+A79+0.25 -> 2016 | B80: 44983.596 | C80: 90.120227 | D80: 3.5733333 | E80: 121.44915 | F80: =100*(LN(E80)-LN(E79)) -> 0.77843534 | G80: 0.28666667 | H80: 109.08185 | I80: =100*(LN(H80)-LN(H79)) -> -0.080195099 | J80: =100 * ((1 + D80 * 0.01) ^ 0.25 / (1 + F81 * 0.01) - 1) -> -0.09000772 | K80: =100 * ((1 + G80 * 0.01) ^ 0.25 / (1 + I81 * 0.01) - 1) -> -0.62814662 | L80: =LN(C80) -> 4.5011446 | M80: =100 * (LN(B80) - LN(B79)) -> 1.3507201 | N80: 99.67 | O80: -0.7880305 | P80: 0.3708649
A81: =+A80+0.25 -> 2016.25 | B81: 44668.774 | C81: 91.210636 | D81: 3.52 | E81: 122.63599 | F81: =100*(LN(E81)-LN(E80)) -> 0.97248925 | G81: 0.25666667 | H81: 109.85268 | I81: =100*(LN(H81)-LN(H80)) -> 0.70415953 | J81: =100 * ((1 + D81 * 0.01) ^ 0.25 / (1 + F82 * 0.01) - 1) -> 0.13744083 | K81: =100 * ((1 + G81 * 0.01) ^ 0.25 / (1 + I82 * 0.01) - 1) -> -0.21245918 | L81: =LN(C81) -> 4.5131715 | M81: =100 * (LN(B81) - LN(B80)) -> -0.70232007 | N81: 100.28 | O81: -0.2820825 | P81: 0.6031494
A82: =+A81+0.25 -> 2016.5 | B82: 44928.384 | C82: 93.895601 | D82: 3.4933333 | E82: 123.53472 | F82: =100*(LN(E82)-LN(E81)) -> 0.73017251 | G82: 0.29666667 | H82: 110.15756 | I82: =100*(LN(H82)-LN(H81)) -> 0.27715302 | J82: =100 * ((1 + D82 * 0.01) ^ 0.25 / (1 + F83 * 0.01) - 1) -> 0.5510923 | K82: =100 * ((1 + G82 * 0.01) ^ 0.25 / (1 + I83 * 0.01) - 1) -> -0.4483917 | L82: =LN(C82) -> 4.5421835 | M82: =100 * (LN(B82) - LN(B81)) -> 0.57950541 | N82: 100.02 | O82: -0.6474357 | P82: -0.2552414
A83: =+A82+0.25 -> 2016.75 | B83: 44875.624 | C83: 95.302514 | D83: 3.48 | E83: 123.91744 | F83: =100*(LN(E83)-LN(E82)) -> 0.30932339 | G83: 0.43 | H83: 110.73722 | I83: =100*(LN(H83)-LN(H82)) -> 0.52482929 | J83: =100 * ((1 + D83 * 0.01) ^ 0.25 / (1 + F84 * 0.01) - 1) -> 0.15237521 | K83: =100 * ((1 + G83 * 0.01) ^ 0.25 / (1 + I84 * 0.01) - 1) -> -0.39500435 | L83: =LN(C83) -> 4.5570562 | M83: =100 * (LN(B83) - LN(B82)) -> -0.11749869 | N83: 98.92 | O83: -1.866671 | P83: -1.100708
A84: =+A83+0.25 -> 2017 | B84: 44745.487 | C84: 97.18326 | D84: 3.22 | E84: 124.79467 | F84: =100*(LN(E84)-LN(E83)) -> 0.70542151 | G84: 0.59 | H84: 111.2971 | I84: =100*(LN(H84)-LN(H83)) -> 0.50432353 | J84: =100 * ((1 + D84 * 0.01) ^ 0.25 / (1 + F85 * 0.01) - 1) -> 0.26139113 | K84: =100 * ((1 + G84 * 0.01) ^ 0.25 / (1 + I85 * 0.01) - 1) -> -0.17256759 | L84: =LN(C84) -> 4.5765985 | M84: =100 * (LN(B84) - LN(B83)) -> -0.29041596 | N84: 101.59 | O84: 0.6341088 | P84: 2.665291
A85: =+A84+0.25 -> 2017.25 | B85: 45173.82 | C85: 94.416836 | D85: 2.5833333 | E85: 125.46119 | F85: =100*(LN(E85)-LN(E84)) -> 0.53267477 | G85: 0.89 | H85: 111.65415 | I85: =100*(LN(H85)-LN(H84)) -> 0.32029509 | J85: =100 * ((1 + D85 * 0.01) ^ 0.25 / (1 + F86 * 0.01) - 1) -> 0.53634684 | K85: =100 * ((1 + G85 * 0.01) ^ 0.25 / (1 + I86 * 0.01) - 1) -> -0.27309683 | L85: =LN(C85) -> 4.5477194 | M85: =100 * (LN(B85) - LN(B84)) -> 0.95271067 | N85: 101.37 | O85: 0.2666197 | P85: -0.2158127
...
